# asyncio_exception_handling

Quero estudar uma forma adequada de lidar com exceções ocorridas em tarefas
executadas concorrentemente com asyncio.gather
